<?xml version="1.0" ?>
<!-- =================================================================================== -->
<!-- |    This document was autogenerated by xacro from pa10_csl.urdf.xacro            | -->
<!-- |    EDITING THIS FILE BY HAND IS NOT RECOMMENDED                                 | -->
<!-- =================================================================================== -->
<robot name="pa10" xmlns:xacro="http://www.ros.org/wiki/xacro">
  <!-- ros_control plugin -->
  <gazebo>
    <plugin filename="libgazebo_ros_control.so" name="gazebo_ros_control">
      <robotNamespace/>
      <robotSimType>gazebo_ros_control/DefaultRobotHWSim</robotSimType>
    </plugin>
  </gazebo>
  <!-- base_link -->
  <gazebo reference="base_link">
    <mu1>0.5</mu1>
    <mu2>0.5</mu2>
    <material>Gazebo/Grey</material>
  </gazebo>
  <!-- Link1 -->
  <gazebo reference="link_shoulder_1">
    <material>Gazebo/Blue</material>
  </gazebo>
  <!-- Link2 -->
  <gazebo reference="link_shoulder_2">
    <mu1>0.5</mu1>
    <mu2>0.5</mu2>
    <material>Gazebo/Grey</material>
  </gazebo>
  <!-- Link3 -->
  <gazebo reference="link_elbow_1">
    <mu1>0.5</mu1>
    <mu2>0.5</mu2>
    <material>Gazebo/Blue</material>
  </gazebo>
  <!-- Link4 -->
  <gazebo reference="link_elbow_2">
    <mu1>0.5</mu1>
    <mu2>0.5</mu2>
    <material>Gazebo/Grey</material>
  </gazebo>
  <!-- Link5 -->
  <gazebo reference="link_wrist_1">
    <mu1>0.5</mu1>
    <mu2>0.5</mu2>
    <material>Gazebo/Blue</material>
  </gazebo>
  <!-- Link6 -->
  <gazebo reference="link_wrist_2">
    <mu1>0.5</mu1>
    <mu2>0.5</mu2>
    <material>Gazebo/Grey</material>
  </gazebo>
  <gazebo reference="link_wrist_2">
    <mu1>0.5</mu1>
    <mu2>0.5</mu2>
    <material>Gazebo/Grey</material>
  </gazebo>
  <gazebo reference="link_gripper_base">
    <mu1>0.5</mu1>
    <mu2>0.5</mu2>
    <material>Gazebo/Grey</material>
  </gazebo>
  <gazebo reference="link_finger_1">
    <mu1>0.5</mu1>
    <mu2>0.5</mu2>
    <material>Gazebo/Orange</material>
  </gazebo>
  <gazebo reference="link_finger_2">
    <mu1>0.5</mu1>
    <mu2>0.5</mu2>
    <material>Gazebo/Orange</material>
  </gazebo>
  <material name="black">
    <color rgba="0.0 0.0 0.0 1.0"/>
  </material>
  <material name="blue">
    <color rgba="0.0 0.0 0.8 1.0"/>
  </material>
  <material name="green">
    <color rgba="0.0 0.8 0.0 1.0"/>
  </material>
  <material name="grey">
    <color rgba="0.2 0.2 0.2 1.0"/>
  </material>
  <material name="orange">
    <color rgba="1.0 0.423529411765 0.0392156862745 1.0"/>
  </material>
  <material name="brown">
    <color rgba="0.870588235294 0.811764705882 0.764705882353 1.0"/>
  </material>
  <material name="red">
    <color rgba="0.8 0.0 0.0 1.0"/>
  </material>
  <material name="white">
    <color rgba="1.0 1.0 1.0 1.0"/>
  </material>
  <!-- LINKS -->
  <link name="world"/>
  <link name="kinect2_rgb_optical_frame">
    <visual>
      <origin rpy="0 0 0" xyz="0 0 0"/>
      <geometry>
        <mesh filename="package://pa10_description/sensors_3D_models/kinect.dae" scale="1 1 1"/>
      </geometry>
      <material name="">
        <color rgba="0.0 0.0 0.0 1.0"/>
      </material>
    </visual>
    <collision>
      <origin rpy="0 0 0" xyz="0 0 0"/>
      <geometry>
        <mesh filename="package://pa10_description/sensors_3D_models/kinect.dae" scale="1 1 1"/>
      </geometry>
    </collision>
    <inertial>
      <origin rpy="0 0 0" xyz="0 0 0"/>
      <mass value="1"/>
      <inertia ixx="1" ixy="0.0" ixz="0.0" iyy="1" iyz="0.0" izz="1"/>
    </inertial>
  </link>
  <link name="base_link">
    <visual>
      <origin rpy="0 0 3.14" xyz="0 0 0"/>
      <geometry>
        <mesh filename="package://pa10_description/pa10_stl/S1.stl" scale="1 1 1"/>
      </geometry>
      <material name="">
        <color rgba="0.34 0.35 0.36 1.0"/>
      </material>
    </visual>
    <collision>
      <origin rpy="0 0 3.14" xyz="0 0 0"/>
      <geometry>
        <mesh filename="package://pa10_description/pa10_stl_collision/S1_collision.stl" scale="1 1 1"/>
      </geometry>
    </collision>
    <inertial>
      <origin rpy="0 0 3.14" xyz="0 0 0"/>
      <mass value="1"/>
      <inertia ixx="1" ixy="0.0" ixz="0.0" iyy="1" iyz="0.0" izz="1"/>
    </inertial>
  </link>
  <link name="link_shoulder_1">
    <visual>
      <origin rpy="0 0 0" xyz="0 0 0.117"/>
      <geometry>
        <mesh filename="package://pa10_description/pa10_stl/S2.stl" scale="1 1 1"/>
      </geometry>
      <material name="">
        <color rgba="0.33 0.96 0.53 1.5"/>
      </material>
    </visual>
    <collision>
      <origin rpy="0 0 0" xyz="0 0 0.117"/>
      <geometry>
        <mesh filename="package://pa10_description/pa10_stl_collision/S2_collision.stl" scale="1 1 1"/>
      </geometry>
    </collision>
    <inertial>
      <origin rpy="0 0 0" xyz="0 0 0.117"/>
      <mass value="1"/>
      <inertia ixx="1" ixy="0.0" ixz="0.0" iyy="1" iyz="0.0" izz="1"/>
    </inertial>
  </link>
  <link name="link_shoulder_2">
    <visual>
      <origin rpy="-1.57079 0 3.14159" xyz="0 0 0"/>
      <geometry>
        <mesh filename="package://pa10_description/pa10_stl/S3.stl" scale="1 1 1"/>
      </geometry>
      <material name="">
        <color rgba="0.34 0.35 0.36 1.0"/>
      </material>
    </visual>
    <collision>
      <origin rpy="-1.57079 0 3.14159" xyz="0 0 0"/>
      <geometry>
        <mesh filename="package://pa10_description/pa10_stl_collision/S3_collision.stl" scale="1 1 1"/>
      </geometry>
    </collision>
    <inertial>
      <origin rpy="-1.57079 0 3.14159" xyz="0 0 0"/>
      <mass value="1"/>
      <inertia ixx="1" ixy="0.0" ixz="0.0" iyy="1" iyz="0.0" izz="1"/>
    </inertial>
  </link>
  <link name="link_shoulder_to_elbow">
    <inertial>
      <origin rpy="0 0 0" xyz="0 0 1"/>
      <mass value="1"/>
      <inertia ixx="1" ixy="0.0" ixz="0.0" iyy="1" iyz="0.0" izz="1"/>
    </inertial>
  </link>
  <link name="link_elbow_1">
    <visual>
      <origin rpy="0 0 0" xyz="0 0.0 0.133"/>
      <geometry>
        <mesh filename="package://pa10_description/pa10_stl/E1.stl" scale="1 1 1"/>
      </geometry>
      <material name="">
        <color rgba="0.33 0.96 0.53 1.5"/>
      </material>
    </visual>
    <collision>
      <origin rpy="0 0 0" xyz="0 0.0 0.133"/>
      <geometry>
        <mesh filename="package://pa10_description/pa10_stl_collision/E1_collision.stl" scale="1 1 1"/>
      </geometry>
    </collision>
    <inertial>
      <origin rpy="0 0 0" xyz="0 0.0 0.133"/>
      <mass value="1"/>
      <inertia ixx="1" ixy="0.0" ixz="0.0" iyy="1" iyz="0.0" izz="1"/>
    </inertial>
  </link>
  <link name="link_elbow_2">
    <visual>
      <origin rpy="1.57079 0 0" xyz="0 0.003 0"/>
      <geometry>
        <mesh filename="package://pa10_description/pa10_stl/E2.stl" scale="1 1 1"/>
      </geometry>
      <material name="">
        <color rgba="0.34 0.35 0.36 1.0"/>
      </material>
    </visual>
    <collision>
      <origin rpy="-1.57079 0 0" xyz="0 0.003 0"/>
      <geometry>
        <mesh filename="package://pa10_description/pa10_stl_collision/E2_collision.stl" scale="1 1 1"/>
      </geometry>
    </collision>
    <inertial>
      <origin rpy="1.57079 0 0" xyz="0 0.003 0"/>
      <mass value="1"/>
      <inertia ixx="1" ixy="0.0" ixz="0.0" iyy="1" iyz="0.0" izz="1"/>
    </inertial>
  </link>
  <link name="link_wrist_1">
    <visual>
      <origin rpy="0 0 0" xyz="0 0 0.195"/>
      <geometry>
        <mesh filename="package://pa10_description/pa10_stl/W1.stl" scale="1 1 1"/>
      </geometry>
      <material name="">
        <color rgba="0.33 0.96 0.53 1.5"/>
      </material>
    </visual>
    <collision>
      <origin rpy="0 0 0" xyz="0 0 0.195"/>
      <geometry>
        <mesh filename="package://pa10_description/pa10_stl_collision/W1_collision.stl" scale="1 1 1"/>
      </geometry>
    </collision>
    <inertial>
      <origin rpy="0 0 0" xyz="0 0 0.195"/>
      <mass value="1"/>
      <inertia ixx="1" ixy="0.0" ixz="0.0" iyy="1" iyz="0.0" izz="1"/>
    </inertial>
  </link>
  <link name="link_wrist_2">
    <visual>
      <origin rpy="1.57079 0 0" xyz="0 0 0"/>
      <geometry>
        <mesh filename="package://pa10_description/pa10_stl/W2.stl" scale="1 1 1"/>
      </geometry>
      <material name="">
        <color rgba="0.34 0.35 0.36 1.0"/>
      </material>
    </visual>
    <collision>
      <origin rpy="1.57079 0 0" xyz="0 0 0"/>
      <geometry>
        <mesh filename="package://pa10_description/pa10_stl_collision/W2_collision.stl" scale="1 1 1"/>
      </geometry>
    </collision>
    <inertial>
      <origin rpy="1.57079 0 0" xyz="0 0 0"/>
      <mass value="1"/>
      <inertia ixx="1" ixy="0.0" ixz="0.0" iyy="1" iyz="0.0" izz="1"/>
    </inertial>
  </link>
  <link name="link_wrist_3"/>
  <link name="link_ee_tool">
    <inertial>
      <origin rpy="0 0 0" xyz="0 0 0"/>
      <mass value="0.05"/>
      <inertia ixx="1" ixy="0.0" ixz="0.0" iyy="1" iyz="0.0" izz="1"/>
    </inertial>
  </link>
  <!-- GRIPPER LINKS -->
  <link name="link_gripper_base">
    <visual>
      <origin rpy="0 0 0" xyz="0 0 -0.045"/>
      <geometry>
        <mesh filename="package://pa10_description/gripper_stl/pa10_gripper_base.stl" scale="1 1 1"/>
      </geometry>
      <material name="">
        <color rgba="0.2 0.2 0.2 1.0"/>
      </material>
    </visual>
    <collision>
      <origin rpy="0 0 0" xyz="0 0 -0.045"/>
      <geometry>
        <mesh filename="package://pa10_description/gripper_stl/pa10_gripper_base.stl" scale="1 1 1"/>
      </geometry>
    </collision>
    <inertial>
      <origin rpy="0 0 0" xyz="0 0 -0.045"/>
      <mass value="0.5"/>
      <inertia ixx="1" ixy="0.0" ixz="0.0" iyy="1" iyz="0.0" izz="1"/>
    </inertial>
  </link>
  <link name="link_finger_1">
    <visual>
      <origin rpy="-3.14159 -1.57079 0" xyz="-0.0225 0.075 -0.01"/>
      <geometry>
        <mesh filename="package://pa10_description/gripper_stl/finger.STL" scale="0.001 0.001 0.001"/>
      </geometry>
      <material name="">
        <color rgba="1.0 0.423529411765 0.0392156862745 1.0"/>
      </material>
    </visual>
    <collision>
      <origin rpy="-3.14159 -1.57079 0" xyz="-0.0225 0.075 -0.01"/>
      <geometry>
        <mesh filename="package://pa10_description/gripper_stl/finger.STL" scale="0.001 0.001 0.001"/>
      </geometry>
    </collision>
    <inertial>
      <origin rpy="0 0 0" xyz="0 0 0"/>
      <mass value="0.1"/>
      <inertia ixx="1" ixy="0.0" ixz="0.0" iyy="1" iyz="0.0" izz="1"/>
    </inertial>
  </link>
  <link name="link_finger_2">
    <visual>
      <origin rpy="0 1.57079 0" xyz="-0.0225 -0.075 0.07"/>
      <geometry>
        <mesh filename="package://pa10_description/gripper_stl/finger_left.STL" scale="0.001 0.001 0.001"/>
      </geometry>
      <material name="">
        <color rgba="1.0 0.423529411765 0.0392156862745 1.0"/>
      </material>
    </visual>
    <collision>
      <origin rpy="0 1.57079 0" xyz="-0.0225 -0.075 0.07"/>
      <geometry>
        <mesh filename="package://pa10_description/gripper_stl/finger_left.STL" scale="0.001 0.001 0.001"/>
      </geometry>
    </collision>
    <inertial>
      <origin rpy="0 0 0" xyz="0 0 0"/>
      <mass value="0.1"/>
      <inertia ixx="1" ixy="0.0" ixz="0.0" iyy="1" iyz="0.0" izz="1"/>
    </inertial>
  </link>
  <!-- *********** -->
  <!--   JOINTS    -->
  <!--************ -->
  <joint name="fixed" type="fixed">
    <parent link="world"/>
    <child link="base_link"/>
  </joint>
  <joint name="kinect" type="fixed">
    <origin rpy="-0.52 0 0" xyz="0 -0.90 0"/>
    <parent link="world"/>
    <child link="kinect2_rgb_optical_frame"/>
  </joint>
  <joint name="S1" type="revolute">
    <origin rpy="0 0 0" xyz="0 0 0.2"/>
    <parent link="base_link"/>
    <child link="link_shoulder_1"/>
    <axis xyz="0 0 1"/>
    <limit effort="39.0" lower="-2.96705972839" upper="2.96705972839" velocity="0.85"/>
    <safety_controller k_position="20" k_velocity="20" soft_lower_limit="-2.94705972839" soft_upper_limit="2.94705972839"/>
  </joint>
  <joint name="S2" type="revolute">
    <origin rpy="-1.57079 0 0" xyz="0 0 0.117"/>
    <parent link="link_shoulder_1"/>
    <child link="link_shoulder_2"/>
    <axis xyz="0 0 1"/>
    <limit effort="39.0" lower="-1.57079632679" upper="1.57079632679" velocity="0.85"/>
    <safety_controller k_position="20" k_velocity="20" soft_lower_limit="-1.55079632679" soft_upper_limit="1.55079632679"/>
  </joint>
  <joint name="soldier_to_elbow_joint" type="fixed">
    <origin rpy="1.57079 0 0" xyz="0 0 0"/>
    <parent link="link_shoulder_2"/>
    <child link="link_shoulder_to_elbow"/>
  </joint>
  <joint name="E1" type="revolute">
    <origin rpy="0 0 0" xyz="0 0 0.317"/>
    <parent link="link_shoulder_to_elbow"/>
    <child link="link_elbow_1"/>
    <axis xyz="0 0 1"/>
    <limit effort="39.0" lower="-2.96705972839" upper="2.96705972839" velocity="1.85"/>
    <safety_controller k_position="20" k_velocity="20" soft_lower_limit="-2.94705972839" soft_upper_limit="2.94705972839"/>
  </joint>
  <joint name="E2" type="revolute">
    <origin rpy="-1.57079  0 0" xyz="0 0 0.133"/>
    <parent link="link_elbow_1"/>
    <child link="link_elbow_2"/>
    <axis xyz="0 0 1"/>
    <limit effort="39.0" lower="-2.26892802759" upper="2.26892802759" velocity="1.85"/>
    <safety_controller k_position="20" k_velocity="20" soft_lower_limit="-2.24892802759" soft_upper_limit="2.24892802759"/>
  </joint>
  <joint name="W1" type="revolute">
    <origin rpy="1.57079 0 0" xyz="0 -0.285 0 "/>
    <parent link="link_elbow_2"/>
    <child link="link_wrist_1"/>
    <axis xyz="0 0 1"/>
    <limit effort="39.0" lower="-4.36332312999" upper="4.36332312999" velocity="1.85"/>
    <safety_controller k_position="20" k_velocity="20" soft_lower_limit="-4.34332312999" soft_upper_limit="4.34332312999"/>
  </joint>
  <joint name="W2" type="revolute">
    <origin rpy="-1.57079 0 0" xyz="0 0 0.195"/>
    <parent link="link_wrist_1"/>
    <child link="link_wrist_2"/>
    <axis xyz="0 0 1"/>
    <limit effort="39.0" lower="-2.79252680319" upper="2.79252680319" velocity="5.65486677646"/>
    <safety_controller k_position="20" k_velocity="20" soft_lower_limit="-2.77252680319" soft_upper_limit="2.77252680319"/>
  </joint>
  <joint name="W3" type="revolute">
    <origin rpy="1.57079 0 0" xyz="0 -0.07 0"/>
    <parent link="link_wrist_2"/>
    <child link="link_wrist_3"/>
    <axis xyz="0 0 1"/>
    <limit effort="39.0" lower="-4.36332312999" upper="4.36332312999" velocity="5.65486677646"/>
    <safety_controller k_position="20" k_velocity="20" soft_lower_limit="-4.34332312999" soft_upper_limit="4.34332312999"/>
  </joint>
  <!-- GRIPPER JOINTS -->
  <joint name="gripper_base" type="fixed">
    <origin rpy="0 0 0" xyz="0 0 0.045"/>
    <parent link="link_wrist_3"/>
    <child link="link_gripper_base"/>
  </joint>
  <joint name="finger_joint_1" type="prismatic">
    <origin rpy="-1.57079 0 0" xyz="0 -0.03 0.11"/>
    <parent link="link_gripper_base"/>
    <child link="link_finger_1"/>
    <axis xyz="0 0 1"/>
    <limit effort="39.0" lower="-0.039" upper="0" velocity="1.0"/>
    <safety_controller k_position="20" k_velocity="20" soft_lower_limit="-0.035" soft_upper_limit="-0.002"/>
  </joint>
  <joint name="finger_joint_2" type="prismatic">
    <origin rpy="1.57079 0 0" xyz="0 0.03 0.11"/>
    <parent link="link_gripper_base"/>
    <child link="link_finger_2"/>
    <axis xyz="0 0 1"/>
    <limit effort="39.0" lower="-0.039" upper="0" velocity="1.0"/>
    <safety_controller k_position="20" k_velocity="20" soft_lower_limit="-0.035" soft_upper_limit="-0.002"/>
  </joint>
  <joint name="ee_tool_frame" type="fixed">
    <origin rpy="0 0 0" xyz="0 0 0.23"/>
    <parent link="link_wrist_3"/>
    <child link="link_ee_tool"/>
  </joint>
  <!-- ******************* -->
  <!--    TRANSMITIONS     -->
  <!-- ******************* -->
  <transmission name="S1_trans">
    <type>transmission_interface/SimpleTransmission</type>
    <actuator name="S1_motor">
      <mechanicalReduction>1.0</mechanicalReduction>
    </actuator>
    <joint name="S1">
      <hardwareInterface>hardware_interface/PositionJointInterface</hardwareInterface>
      <hardwareInterface>hardware_interface/EffortJointInterface</hardwareInterface>
    </joint>
  </transmission>
  <transmission name="S2_trans">
    <type>transmission_interface/SimpleTransmission</type>
    <actuator name="S2_motor">
      <mechanicalReduction>1.0</mechanicalReduction>
    </actuator>
    <joint name="S2">
      <hardwareInterface>hardware_interface/PositionJointInterface</hardwareInterface>
      <hardwareInterface>hardware_interface/EffortJointInterface</hardwareInterface>
    </joint>
  </transmission>
  <transmission name="E1_trans">
    <type>transmission_interface/SimpleTransmission</type>
    <actuator name="E1_motor">
      <mechanicalReduction>1.0</mechanicalReduction>
    </actuator>
    <joint name="E1">
      <hardwareInterface>hardware_interface/PositionJointInterface</hardwareInterface>
      <hardwareInterface>hardware_interface/EffortJointInterface</hardwareInterface>
    </joint>
  </transmission>
  <transmission name="E2_trans">
    <type>transmission_interface/SimpleTransmission</type>
    <actuator name="E2_motor">
      <mechanicalReduction>1.0</mechanicalReduction>
    </actuator>
    <joint name="E2">
      <hardwareInterface>hardware_interface/PositionJointInterface</hardwareInterface>
      <hardwareInterface>hardware_interface/EffortJointInterface</hardwareInterface>
    </joint>
  </transmission>
  <transmission name="W1_trans">
    <type>transmission_interface/SimpleTransmission</type>
    <actuator name="W1_motor">
      <mechanicalReduction>1.0</mechanicalReduction>
    </actuator>
    <joint name="W1">
      <hardwareInterface>hardware_interface/PositionJointInterface</hardwareInterface>
      <hardwareInterface>hardware_interface/EffortJointInterface</hardwareInterface>
    </joint>
  </transmission>
  <transmission name="W2_trans">
    <type>transmission_interface/SimpleTransmission</type>
    <actuator name="W2_motor">
      <mechanicalReduction>1.0</mechanicalReduction>
    </actuator>
    <joint name="W2">
      <hardwareInterface>hardware_interface/PositionJointInterface</hardwareInterface>
      <hardwareInterface>hardware_interface/EffortJointInterface</hardwareInterface>
    </joint>
  </transmission>
  <transmission name="W3_trans">
    <type>transmission_interface/SimpleTransmission</type>
    <actuator name="W3_motor">
      <mechanicalReduction>1.0</mechanicalReduction>
    </actuator>
    <joint name="W3">
      <hardwareInterface>hardware_interface/PositionJointInterface</hardwareInterface>
      <hardwareInterface>hardware_interface/EffortJointInterface</hardwareInterface>
    </joint>
  </transmission>
  <transmission name="finger_joint_1_trans">
    <type>transmission_interface/SimpleTransmission</type>
    <actuator name="finger_joint_1_motor">
      <mechanicalReduction>1.0</mechanicalReduction>
    </actuator>
    <joint name="finger_joint_1">
      <hardwareInterface>hardware_interface/PositionJointInterface</hardwareInterface>
      <hardwareInterface>hardware_interface/EffortJointInterface</hardwareInterface>
    </joint>
  </transmission>
  <transmission name="finger_joint_2_trans">
    <type>transmission_interface/SimpleTransmission</type>
    <actuator name="finger_joint_2_motor">
      <mechanicalReduction>1.0</mechanicalReduction>
    </actuator>
    <joint name="finger_joint_2">
      <hardwareInterface>hardware_interface/PositionJointInterface</hardwareInterface>
      <hardwareInterface>hardware_interface/EffortJointInterface</hardwareInterface>
    </joint>
  </transmission>
</robot>
