<?xml version="1.0" ?>

<robot name="pa10" xmlns:xacro="http://www.ros.org/wiki/xacro">


	<!-- Used for fixing robot to Gazebo 'base_link' -->
  <link name="world"/>

  <joint name="fixed" type="fixed">
    <parent link="world"/>
    <child link="base_link"/>
  </joint>

	<!-- Import all Gazebo-customization elements, including Gazebo colors -->
  <xacro:include filename="$(find pa10_description)/urdf/pa10.gazebo" />
  <!-- Import Rviz colors -->
  <xacro:include filename="$(find pa10_description)/urdf/materials.xacro" />



  <link name="base_link">
    <visual>
      <origin rpy="0 0 3.14" xyz="0 0 0"/>
      <geometry>
        <mesh filename="$(find pa10)/pa10_stl/S1.stl"/>


<!-- podemos usar tambien en vez de mesh que requiere un archivo, cilindros cajas o esferas!!! -->

      </geometry>
      <material name="">
        <color rgba="0.34 0.35 0.36 1.0"/>
      </material>
    </visual>
    <collision>
      <origin rpy="0 0 3.14" xyz="0 0 0"/>
      <geometry>
        <mesh filename="$(find pa10)/pa10_stl_collision/S1_collision.stl"/>
      </geometry>
    </collision>
    <inertial>
      <origin xyz="0 0 1" rpy="0 0 0"/>
      <mass value="1"/>
      <inertia
	  ixx="1" ixy="0.0" ixz="0.0"
	  iyy="1" iyz="0.0"
	  izz="1"/>
    </inertial>
  </link>
<link name="link_1">
    <visual>
      <origin rpy="0 0 0" xyz="0 0 0.117"/>
      <geometry>
        <mesh filename="$(find pa10)/pa10_stl/S2.stl"/>

      </geometry>
	<material name="">
        <color rgba="0.33 0.96 0.53 1.5"/>
      </material>
    </visual>
    <collision>
      <origin rpy="0 0 0" xyz="0 0 0.117"/>
      <geometry>
        <mesh filename="$(find pa10)/pa10_stl_collision/S2_collision.stl"/>
      </geometry>
    </collision>
    <inertial>
      <origin xyz="0 0 1" rpy="0 0 0"/>
      <mass value="1"/>
      <inertia
	  ixx="1" ixy="0.0" ixz="0.0"
	  iyy="1" iyz="0.0"
	  izz="1"/>
    </inertial>
  </link>
<link name="link_2">
    <visual>
      <origin rpy="0 0 0" xyz="0 0 0"/>
      <geometry>
        <mesh filename="$(find pa10)/pa10_stl/S3.stl"/>

      </geometry>
      <material name="">
        <color rgba="0.34 0.35 0.36 1.0"/>
      </material>
    </visual>
    <collision>
      <origin rpy="0 0 0" xyz="0 0 0"/>
      <geometry>
        <mesh filename="$(find pa10)/pa10_stl_collision/S3_collision.stl"/>
      </geometry>
    </collision>
    <inertial>
      <origin xyz="0 0 1" rpy="0 0 0"/>
      <mass value="1"/>
      <inertia
	  ixx="1" ixy="0.0" ixz="0.0"
	  iyy="1" iyz="0.0"
	  izz="1"/>
    </inertial>
  </link>
<link name="link_3">
    <visual>
      <origin rpy="0 0 0" xyz="0 0 0.133"/>
      <geometry>
        <mesh filename="$(find pa10)/pa10_stl/E1.stl"/>

      </geometry>
	<material name="">
        <color rgba="0.33 0.96 0.53 1.5"/>
      </material>
    </visual>
    <collision>
      <origin rpy="0 0 0" xyz="0 0 0.133"/>
      <geometry>
        <mesh filename="$(find pa10)/pa10_stl_collision/E1_collision.stl"/>
      </geometry>
    </collision>
    <inertial>
      <origin xyz="0 0 1" rpy="0 0 0"/>
      <mass value="1"/>
      <inertia
	  ixx="1" ixy="0.0" ixz="0.0"
	  iyy="1" iyz="0.0"
	  izz="1"/>
    </inertial>
  </link>
<link name="link_4">
    <visual>
      <origin rpy="0 0 0" xyz="0 0.003 0"/>
      <geometry>
        <mesh filename="$(find pa10)/pa10_stl/E2.stl"/>

      </geometry>
	<material name="">
        <color rgba="0.34 0.35 0.36 1.0"/>
      </material>
    </visual>
    <collision>
      <origin rpy="0 0 0" xyz="0 0.003 0"/>
      <geometry>
        <mesh filename="$(find pa10)/pa10_stl_collision/E2_collision.stl"/>
      </geometry>
    </collision>
    <inertial>
      <origin xyz="0 0 1" rpy="0 0 0"/>
      <mass value="1"/>
      <inertia
	  ixx="1" ixy="0.0" ixz="0.0"
	  iyy="1" iyz="0.0"
	  izz="1"/>
    </inertial>
  </link>
<link name="link_5">
    <visual>
      <origin rpy="0 0 0" xyz="0 0 0.195"/>
      <geometry>
        <mesh filename="$(find pa10)/pa10_stl/W1.stl"/>

      </geometry>
	<material name="">
        <color rgba="0.33 0.96 0.53 1.5"/>
      </material>
    </visual>
    <collision>
      <origin rpy="0 0 0" xyz="0 0 0.195"/>
      <geometry>
        <mesh filename="$(find pa10)/pa10_stl_collision/W1_collision.stl"/>
      </geometry>
    </collision>
    <inertial>
      <origin xyz="0 0 1" rpy="0 0 0"/>
      <mass value="1"/>
      <inertia
	  ixx="1" ixy="0.0" ixz="0.0"
	  iyy="1" iyz="0.0"
	  izz="1"/>
    </inertial>
  </link>
<link name="link_6">
    <visual>
      <origin rpy="0 0 0" xyz="0 0 0"/>
      <geometry>
        <mesh filename="$(find pa10)/pa10_stl/W2.stl"/>

      </geometry>
	<material name="">
        <color rgba="0.34 0.35 0.36 1.0"/>
      </material>
    </visual>
    <collision>
      <origin rpy="0 0 0" xyz="0 0 0"/>
      <geometry>
        <mesh filename="$(find pa10)/pa10_stl_collision/W2_collision.stl"/>
      </geometry>
    </collision>
    <inertial>
      <origin xyz="0 0 1" rpy="0 0 0"/>
      <mass value="1"/>
      <inertia
	  ixx="1" ixy="0.0" ixz="0.0"
	  iyy="1" iyz="0.0"
	  izz="1"/>
    </inertial>
  </link>

  <link name = "ee_link"/>



<joint name="S1" type="revolute">
    <origin rpy="0 0 0" xyz="0 0 0.2"/>
    <parent link="base_link"/>
    <child link="link_1"/>
    <axis xyz="0 0 1"/>
    <limit effort="0" lower="-3.089" upper="3.089" velocity="1.0"/>
  </joint>
<joint name="S2" type="revolute">
    <origin rpy="0 0 0" xyz="0 0 0.117"/>
    <parent link="link_1"/>
    <child link="link_2"/>
    <axis xyz="0 1 0"/>
    <limit effort="0" lower="-1.64" upper="1.64" velocity="1.0"/>
  </joint>
<joint name="S3" type="revolute">
    <origin rpy="0 0 0" xyz="0 0 0.317"/>
    <parent link="link_2"/>
    <child link="link_3"/>
    <axis xyz="0 0 1"/>
    <limit effort="0" lower="-3.036" upper="3.036" velocity="1.0"/>
  </joint>
<joint name="E1" type="revolute">
    <origin rpy="0 0 0" xyz="0 0 0.133"/>
    <parent link="link_3"/>
    <child link="link_4"/>
    <axis xyz="0 1 0"/>
    <limit effort="0" lower="-2.39" upper="2.39" velocity="1.0"/>
  </joint>
<joint name="E2" type="revolute">
    <origin rpy="0 0 0" xyz="0 0 0.285"/>
    <parent link="link_4"/>
    <child link="link_5"/>
    <axis xyz="0 0 1"/>
    <limit effort="0" lower="-4.45" upper="4.45" velocity="1.0"/>
  </joint>
<joint name="W1" type="revolute">
    <origin rpy="0 0 0" xyz="0 0 0.195"/>
    <parent link="link_5"/>
    <child link="link_6"/>
    <axis xyz="0 1 0"/>
    <limit effort="0" lower="-2.878" upper="2.878" velocity="1.0"/>
  </joint>
  <joint name = "W2" type="revolute">
    <origin rpy="0 0 0" xyz="0 0 0"/>
    <parent link="link_6"/>
    <child link="ee_link"/>
    <axis xyz="0 0 1"/>
    <limit effort="0" lower="-2.878" upper="2.878" velocity="1.0"/>
  </joint>




</robot>
